Workbook

Sheet CER
A1: fecha | B1: cer | C1: Cer Balanz | D1: Cer Rem | E1: Cer Comafi
A2: 37972 | B2: 1.4552 | C2: 1.4552 | D2: 1.4552 | E2: 1.4552
A3: 43486 | B3: 12.5906 | C3: 12.5906 | D3: 12.5906 | E3: 12.5906
A4: 43487 | B4: 12.601 | C4: 12.601 | D4: 12.601 | E4: 12.601
A5: 43488 | B5: 12.6115 | C5: 12.6115 | D5: 12.6115 | E5: 12.6115
A6: 43489 | B6: 12.6219 | C6: 12.6219 | D6: 12.6219 | E6: 12.6219
A7: 43490 | B7: 12.6324 | C7: 12.6324 | D7: 12.6324 | E7: 12.6324
A8: 43491 | B8: 12.6428 | C8: 12.6428 | D8: 12.6428 | E8: 12.6428
A9: 43492 | B9: 12.6533 | C9: 12.6533 | D9: 12.6533 | E9: 12.6533
A10: 43493 | B10: 12.6638 | C10: 12.6638 | D10: 12.6638 | E10: 12.6638
A11: 43494 | B11: 12.6743 | C11: 12.6743 | D11: 12.6743 | E11: 12.6743
A12: 43495 | B12: 12.6848 | C12: 12.6848 | D12: 12.6848 | E12: 12.6848
A13: 43496 | B13: 12.6953 | C13: 12.6953 | D13: 12.6953 | E13: 12.6953
... A2584: 46067 | B2584: 703.4916 | C2584: 703.4916 | D2584: 703.4916 | E2584: 703.4916
A2585: 46068 | B2585: 704.1185 | C2585: 704.1185 | D2585: 704.1185 | E2585: 704.1185 | F2585: dic
A2586: 46069 | B2586: 704.8378 | C2586: 704.8378 | D2586: 704.8378 | E2586: 704.8378
A2587: 46070 | B2587: 705.5578 | C2587: 705.5578 | D2587: 705.5578 | E2587: 705.5578
A2588: 46071 | B2588: 706.2785 | C2588: 706.2785 | D2588: 706.2785 | E2588: 706.2785
A2589: 46072 | B2589: 707 | C2589: 707 | D2589: 707 | E2589: 707
A2590: 46073 | B2590: 707.7222 | C2590: 707.7222 | D2590: 707.7222 | E2590: 707.7222
A2591: 46074 | B2591: 708.4451 | C2591: 708.4451 | D2591: 708.4451 | E2591: 708.4451
A2592: 46075 | B2592: 709.1688 | C2592: 709.1688 | D2592: 709.1688 | E2592: 709.1688
A2593: 46076 | B2593: 709.8932 | C2593: 709.8932 | D2593: 709.8932 | E2593: 709.8932
A2594: 46077 | B2594: 710.6184 | C2594: 710.6184 | D2594: 710.6184 | E2594: 710.6184
A2595: 46078 | B2595: 711.3442 | C2595: 711.3442 | D2595: 711.3442 | E2595: 711.3442
A2596: 46079 | B2596: 712.0709 | C2596: 712.0709 | D2596: 712.0709 | E2596: 712.0709
A2597: 46080 | B2597: 712.7983 | C2597: 712.7983 | D2597: 712.7983 | E2597: 712.7983
... A2612: 46095 | B2612: 723.7986 | C2612: 723.7986 | D2612: 723.7986 | E2612: 723.7986
A2613: 46096 | B2613: 724.5379 | C2613: 724.5379 | D2613: 724.5379 | E2613: 724.5379 | F2613: ene
A2614: 46097 | B2614: 725.20641 | C2614: 725.20641 | D2614: 725.20641 | E2614: 725.20641
A2615: 46098 | B2615: 725.87549 | C2615: 725.87549 | D2615: 725.87549 | E2615: 725.87549
A2616: 46099 | B2616: 726.54518 | C2616: 726.54518 | D2616: 726.54518 | E2616: 726.54518
A2617: 46100 | B2617: 727.21549 | C2617: 727.21549 | D2617: 727.21549 | E2617: 727.21549
A2618: 46101 | B2618: 727.88642 | C2618: 727.88642 | D2618: 727.88642 | E2618: 727.88642
A2619: 46102 | B2619: 728.55797 | C2619: 728.55797 | D2619: 728.55797 | E2619: 728.55797
A2620: 46103 | B2620: 729.23014 | C2620: 729.23014 | D2620: 729.23014 | E2620: 729.23014
A2621: 46104 | B2621: 729.90293 | C2621: 729.90293 | D2621: 729.90293 | E2621: 729.90293
A2622: 46105 | B2622: 730.57634 | C2622: 730.57634 | D2622: 730.57634 | E2622: 730.57634
A2623: 46106 | B2623: 731.25037 | C2623: 731.25037 | D2623: 731.25037 | E2623: 731.25037
A2624: 46107 | B2624: 731.92502 | C2624: 731.92502 | D2624: 731.92502 | E2624: 731.92502
...

Sheet INFLA
A2: Mes/Año | B2: Inflación Proy Balanz | C2: REM | D2: Comafi Base marzo
A3: 46023 | B3: 0.029 | D3: =+B3 -> 0.029
A4: 46054 | B4: 0.029 | D4: =+B4 -> 0.029
A5: 46082 | B5: 0.027 | C5: 0.03 | D5: 0.032
A6: 46113 | B6: 0.021 | C6: 0.022 | D6: 0.027
A7: 46143 | B7: 0.019 | C7: 0.019 | D7: 0.024
A8: 46174 | B8: 0.018 | C8: 0.018 | D8: 0.022
A9: 46204 | B9: 0.017 | C9: 0.017 | D9: 0.022
A10: 46235 | B10: 0.017 | C10: 0.015 | D10: 0.02
A11: 46266 | B11: 0.017 | D11: 0.02
A12: 46296 | B12: 0.017 | D12: 0.019 | H12: =20025872*0.995 -> 19925743
A13: 46327 | B13: 0.017 | D13: 0.019 | H13: 874
A14: 46357 | B14: 0.017 | D14: 0.018 | H14: =+H12/H13 -> 22798.333
D16: 0.32

Sheet FLUJOS
A1: bpy26
A2: Payment Date | B2: Interest | C2: Principal | D2: Flujo Total
A3: 45900 | B3: 0.75 | C3: 0 | D3: 0.75
A4: 45991 | B4: 0.75 | C4: 33 | D4: 33.75
A5: 46081 | B5: 0.49 | C5: 33 | D5: 33.49 | H5: 45412 | I5: TZXM6
A6: 46173 | B6: 0.26 | C6: 34 | D6: 34.26 | H6: 45323 | I6: TZX26
H7: 44078 | I7: TX26
A8: TZX26 | H8: 45596 | I8: TZXO6
A9: Payment Date | B9: Interest | C9: Principal | D9: Flujo Total | H9: 45366 | I9: TZXD6
A10: 45323 | H10: 45432 | I10: TZXM7
A11: 46203 | B11: =100*L9 -> 0 | C11: 0 | D11: =B11+C11 -> 0 | H11: 45989 | I11: TZXA7
H12: 46006 | I12: TZXY7
A13: TZX27 | H13: 45323 | I13: TZX27
A14: Payment Date | B14: Interest | C14: Principal | D14: Flujo Total | H14: 45366 | I14: TZXD7
A15: 45323 | H15: 45323 | I15: TZX28
A16: 46568 | B16: =100*L14 -> 0 | C16: 0 | D16: =B16+C16 -> 0 | H16: 44078 | I16: TX28
H17: 44712 | I17: TX31
A18: TZX28 | H18: 37986 | I18: DICP
A19: Payment Date | B19: Interest | C19: Principal | D19: Flujo Total | H19: 37986 | I19: PARP
A20: 45323 | H20: 37986 | I20: CUAP
A21: 46934 | B21: =100*L19 -> 0 | C21: 0 | D21: =B21+C21 -> 0 | H21: 45989 | I21: X29Y6
H22: 46006 | I22: X30N6
A23: TZXO5
A24: Payment Date | B24: Interest | C24: Principal | D24: Flujo Total
A25: 45596
A26: 45961 | B26: =100*L24 -> 0 | C26: 0 | D26: =B26+C26 -> 0
A28: TZXD5
A29: Payment Date | B29: Interest | C29: Principal | D29: Flujo Total
A30: 45366
A31: 46006 | B31: =100*L29 -> 0 | C31: 0 | D31: =B31+C31 -> 0
A33: TZXM6
A34: Payment Date | B34: Interest | C34: Principal | D34: Flujo Total
A35: 45412
A36: 46112 | B36: =100*L34 -> 0 | C36: 0 | D36: =B36+C36 -> 0
A38: TZXO6
A39: Payment Date | B39: Interest | C39: Principal | D39: Flujo Total
A40: 45596
A41: 46326 | B41: =100*L39 -> 0 | C41: 0 | D41: =B41+C41 -> 0
A43: TZXD6
A44: Payment Date | B44: Interest | C44: Principal | D44: Flujo Total
...
